{
 "cells": [
  {
   "cell_type": "markdown",
   "metadata": {},
   "source": [
    "# Practice Notebook - Errors and Exceptions"
   ]
  },
  {
   "cell_type": "code",
   "execution_count": null,
   "metadata": {},
   "outputs": [],
   "source": []
  },
  {
   "cell_type": "markdown",
   "metadata": {},
   "source": [
    "Below we have a function that removes an item from an input list.  Run it to see what it does."
   ]
  },
  {
   "cell_type": "code",
   "execution_count": null,
   "metadata": {},
   "outputs": [],
   "source": [
    "my_list = [27, 5, 9, 6, 8]\n",
    "\n",
    "def RemoveValue(myVal):\n",
    "    my_list.remove(myVal)\n",
    "    return my_list\n",
    "\n",
    "print(RemoveValue(27))"
   ]
  },
  {
   "cell_type": "markdown",
   "metadata": {},
   "source": [
    "We used the `RemoveValue()` function to remove the number, 27 from the given list.  Great! The function seems to be working fine.  However, there is a problem when we try to call the function on the number 27 again.  Run the following cell to see what happens.  "
   ]
  },
  {
   "cell_type": "code",
   "execution_count": null,
   "metadata": {},
   "outputs": [],
   "source": [
    "print(RemoveValue(27))"
   ]
  },
  {
   "cell_type": "markdown",
   "metadata": {},
   "source": [
    "From the above output we see that our function now raises a <font color=red>**ValueError**</font>.  This is because we are trying to remove a number from a list that is not in the list.  When we removed 27 from the list the first time, it was no longer available in the list to be removed a second time. Python is letting us know that the number 27 no longer makes sense for our `RemoveValue()` function. \n",
    "<br><br>\n",
    "We'd like to take control of the error messaging here and pre-empt this error. Fill in the blanks below to raise a ValueError in the `RemoveValue()` function if a value is not in the list. You can have the error message say something obvious like \"Value must be in the given list\"."
   ]
  },
  {
   "cell_type": "code",
   "execution_count": null,
   "metadata": {},
   "outputs": [],
   "source": [
    "def RemoveValue(myVal):\n",
    "    if myVal not in my_list:\n",
    "        print(\"Value not in list\")\n",
    "    else:\n",
    "        my_list.remove(myVal)\n",
    "    return my_list\n",
    "\n",
    "print(RemoveValue(27))"
   ]
  },
  {
   "cell_type": "markdown",
   "metadata": {},
   "source": [
    "Did your error message print correctly? Was the output something like: **<font color=red>ValueError:</font> Value must be in the given list**? If not, go back to the previous cell and make sure you filled in the blanks correctly.  If your error message did print correctly, great! You are on your way to mastering the basics of handling errors and exceptions.\n",
    "<br><br>\n",
    "Now, let's look at a different function.  Below we have a function that sorts an input list alphabetically.  Run it to see what it does."
   ]
  },
  {
   "cell_type": "code",
   "execution_count": null,
   "metadata": {},
   "outputs": [],
   "source": [
    "my_word_list = ['east', 'after', 'up', 'over', 'inside']\n",
    "\n",
    "def OrganizeList(myList):\n",
    "    myList.sort()\n",
    "    return myList\n",
    "\n",
    "print(OrganizeList(my_word_list))"
   ]
  },
  {
   "cell_type": "markdown",
   "metadata": {},
   "source": [
    "We used the `OrganizeList()` function to sort a given list alphabetically.  The function seems to be working fine.  However, there is a problem when we try to call the function on a list containing number values.  Run the following cell to see what happens."
   ]
  },
  {
   "cell_type": "code",
   "execution_count": null,
   "metadata": {},
   "outputs": [],
   "source": [
    "my_new_list = [6, 3, 8, \"12\", 42]\n",
    "print(OrganizeList(my_new_list))"
   ]
  },
  {
   "cell_type": "markdown",
   "metadata": {},
   "source": [
    "From the above output we see that our function now raises a <font color=red>**TypeError**</font>. This is because the `OrganizeList()` function makes sense for lists that are filled with only strings.  Take control of the error messaging here and pre-empt this error by filling in the blanks below to add an assert type argument that verifies whether the input list is filled with only strings. You can have the error message say something like \"Word list must be a list of strings\"."
   ]
  },
  {
   "cell_type": "code",
   "execution_count": null,
   "metadata": {},
   "outputs": [],
   "source": [
    "def OrganizeList(myList):\n",
    "    for item in myList:\n",
    "        if type(item) != int:\n",
    "            print(\"Error: List contains non-integer values\")\n",
    "            return\n",
    "    myList.sort()\n",
    "    return myList\n",
    "\n",
    "print(OrganizeList(my_new_list))"
   ]
  },
  {
   "cell_type": "markdown",
   "metadata": {},
   "source": [
    "Did your error message print correctly? Was the output something like: **<font color=red>AssertionError:</font> Word list must be a list of strings**? If not, go back to the previous cell and make sure you filled in the blanks correctly. If your error message did print correctly, excellent! You are another step closer to mastering the basics of handling errors and exceptions.\n",
    "<br><br>\n",
    "Let's look at one last code block.  The `Guess()` function below takes a list of participants, assigns each a random number from 1 to 9, and stores this information in a dictionary with the participant name as the key.  It then returns *True* if Larry was assigned the number 9 and *False* if this was not the case. Run it to see what it does."
   ]
  },
  {
   "cell_type": "code",
   "execution_count": null,
   "metadata": {},
   "outputs": [],
   "source": [
    "import random\n",
    "\n",
    "participants = ['Jack','Jill','Larry','Tom']\n",
    "\n",
    "def Guess(participants):\n",
    "    my_participant_dict = {}\n",
    "    for participant in participants:\n",
    "        my_participant_dict[participant] = random.randint(1, 9)\n",
    "    if my_participant_dict['Larry'] == 9:\n",
    "        return True\n",
    "    else:\n",
    "        return False\n",
    "    \n",
    "print(Guess(participants))"
   ]
  },
  {
   "cell_type": "markdown",
   "metadata": {},
   "source": [
    "The code seems to be working fine.  However, there are some things that could go wrong, so find the part that might throw an exception and wrap it in a try-except block to ensure that you get sensible behavior.  Do this in the cell below. Code your function to return *None* if an exception occurs."
   ]
  },
  {
   "cell_type": "code",
   "execution_count": null,
   "metadata": {},
   "outputs": [
    {
     "ename": "",
     "evalue": "",
     "output_type": "error",
     "traceback": [
      "\u001b[1;31mNo se pudo iniciar el kernel porque falta el módulo 'wcwidth'. Considere la posibilidad de instalar este módulo.\n",
      "\u001b[1;31mHaga clic <a href='https://aka.ms/kernelFailuresMissingModule'>aquí</a> para obtener más información."
     ]
    }
   ],
   "source": [
    "# Revised Guess() function\n",
    "def Guess(participants):\n",
    "    my_participant_dict = {}\n",
    "    for participant in participants:\n",
    "        my_participant_dict[participant] = random.randint(1, 9)\n",
    "    try:\n",
    "        if my_participant_dict['Larry'] == 9:\n",
    "            return True\n",
    "        else:\n",
    "            return None"
   ]
  },
  {
   "cell_type": "markdown",
   "metadata": {},
   "source": [
    "Call your revised `Guess()` function with the following participant list."
   ]
  },
  {
   "cell_type": "code",
   "execution_count": null,
   "metadata": {},
   "outputs": [],
   "source": [
    "participants = ['Cathy','Fred','Jack','Tom']\n",
    "print(Guess(participants))"
   ]
  },
  {
   "cell_type": "markdown",
   "metadata": {},
   "source": [
    "Was the above output *None*? If not, go back to the code block containing your revised `Guess()` function and make edits so that the output is *None* for the previous code block.  If the above output was indeed *None*, congratulations! You've mastered the basics of handling errors and exceptions in Python and you are all done with this notebook!"
   ]
  }
 ],
 "metadata": {
  "kernelspec": {
   "display_name": "Python 3",
   "language": "python",
   "name": "python3"
  },
  "language_info": {
   "codemirror_mode": {
    "name": "ipython",
    "version": 3
   },
   "file_extension": ".py",
   "mimetype": "text/x-python",
   "name": "python",
   "nbconvert_exporter": "python",
   "pygments_lexer": "ipython3",
   "version": "3.10.7"
  },
  "vscode": {
   "interpreter": {
    "hash": "fb4569285eef3a3450cb62085a5b1e0da4bce0af555edc33dcf29baf3acc1368"
   }
  }
 },
 "nbformat": 4,
 "nbformat_minor": 2
}
